<?xml version="1.0"?>
<!-- This URDF was automatically created by SolidWorks to URDF Exporter! Originally created by Stephen Brawner (brawner@gmail.com) 
     Commit Version: 1.6.0-4-g7f85cfe  Build Version: 1.6.7995.38578
     For more information, please see http://wiki.ros.org/sw_urdf_exporter -->
<robot
  name="car_and_trailer" xmlns:xacro="http://ros.org/wiki/xacro">
  <link
    name="base_link">
    <inertial>
      <origin
        xyz="0.254 0.442216009225132 0.0199373734974326"
        rpy="0 0 0" />
      <mass
        value="45.8674211610964" />
      <inertia
        ixx="4.71504582583239"
        ixy="-7.73092194649668E-17"
        ixz="-1.15927084096081E-16"
        iyy="1.08472485190803"
        iyz="-0.316618072863205"
        izz="5.55558636298786" />
    </inertial>
    <visual>
      <origin
        xyz="0 0 0"
        rpy="0 0 0" />
      <geometry>
        <mesh
          filename="package://car_and_trailer/meshes/base_link.STL" />
      </geometry>
      <material
        name="">
        <color
          rgba="0.792156862745098 0.819607843137255 0.933333333333333 1" />
      </material>
    </visual>
    <collision>
      <origin
        xyz="0 0 0"
        rpy="0 0 0" />
      <geometry>
        <mesh
          filename="package://car_and_trailer/meshes/base_link.STL" />
      </geometry>
    </collision>
  </link>
  <link
    name="Steer_Left">
    <inertial>
      <origin
        xyz="-0.488789550969635 1.0033 0.0730308461748111"
        rpy="0 0 0" />
      <mass
        value="0.205068851277686" />
      <inertia
        ixx="0.000542814148788568"
        ixy="8.49018783728658E-19"
        ixz="-7.80565059903451E-05"
        iyy="0.000546349438812291"
        iyz="1.09592188639126E-18"
        izz="9.40760107910819E-05" />
    </inertial>
    <visual>
      <origin
        xyz="0 0 0"
        rpy="0 0 0" />
      <geometry>
        <mesh
          filename="package://car_and_trailer/meshes/Steer_Left.STL" />
      </geometry>
      <material
        name="">
        <color
          rgba="0.792156862745098 0.819607843137255 0.933333333333333 1" />
      </material>
    </visual>
    <collision>
      <origin
        xyz="0 0 0"
        rpy="0 0 0" />
      <geometry>
        <mesh
          filename="package://car_and_trailer/meshes/Steer_Left.STL" />
      </geometry>
    </collision>
  </link>
  <joint
    name="Left_Steer"
    type="fixed">
    <origin
      xyz="0.508 2.0066 0"
      rpy="3.14159265358979 0 0" />
    <parent
      link="base_link" />
    <child
      link="Steer_Left" />
    <axis
      xyz="0 0 0" />
  </joint>
  <link
    name="Left_Front_Wheel">
    <inertial>
      <origin
        xyz="-2.22044604925031E-16 0 -0.0254"
        rpy="0 0 0" />
      <mass
        value="1.62962959682595" />
      <inertia
        ixx="0.00460132751039961"
        ixy="-7.56314231045415E-39"
        ixz="-9.18354961579912E-39"
        iyy="0.00460132751039961"
        iyz="-8.3042856448893E-36"
        izz="0.00850174046700706" />
    </inertial>
    <visual>
      <origin
        xyz="0 0 0"
        rpy="0 0 0" />
      <geometry>
        <mesh
          filename="package://car_and_trailer/meshes/Left_Front_Wheel.STL" />
      </geometry>
      <material
        name="">
        <color
          rgba="0.792156862745098 0.819607843137255 0.933333333333333 1" />
      </material>
    </visual>
    <collision>
      <origin
        xyz="0 0 0"
        rpy="0 0 0" />
      <geometry>
        <mesh
          filename="package://car_and_trailer/meshes/Left_Front_Wheel.STL" />
      </geometry>
    </collision>
  </link>
  <joint
    name="Left_Front_Wheel_joint"
    type="continuous">
    <origin
      xyz="-0.4826 1.0033 0.1651"
      rpy="-1.5707963267949 0 -1.5707963267949" />
    <parent
      link="Steer_Left" />
    <child
      link="Left_Front_Wheel" />
    <axis
      xyz="0 0 1" />
  </joint>
  <link
    name="Steer_Right">
    <inertial>
      <origin
        xyz="-0.488789550969635 1.0033 0.073030846174811"
        rpy="0 0 0" />
      <mass
        value="0.205068851277686" />
      <inertia
        ixx="0.000542814148788574"
        ixy="3.00990364412103E-20"
        ixz="-7.80565059903447E-05"
        iyy="0.00054634943881229"
        iyz="3.72059530276015E-20"
        izz="9.4076010791088E-05" />
    </inertial>
    <visual>
      <origin
        xyz="0 0 0"
        rpy="0 0 0" />
      <geometry>
        <mesh
          filename="package://car_and_trailer/meshes/Steer_Right.STL" />
      </geometry>
      <material
        name="">
        <color
          rgba="0.792156862745098 0.819607843137255 0.933333333333333 1" />
      </material>
    </visual>
    <collision>
      <origin
        xyz="0 0 0"
        rpy="0 0 0" />
      <geometry>
        <mesh
          filename="package://car_and_trailer/meshes/Steer_Right.STL" />
      </geometry>
    </collision>
  </link>
  <joint
    name="Rigth_Steer"
    type="fixed">
    <origin
      xyz="0 0 0"
      rpy="3.14159265358979 0 3.14159265358979" />
    <parent
      link="base_link" />
    <child
      link="Steer_Right" />
    <axis
      xyz="0 0 0" />
  </joint>
  <link
    name="Rigth_Front_Wheel">
    <inertial>
      <origin
        xyz="0 0 0.0254"
        rpy="0 0 0" />
      <mass
        value="1.62962959682594" />
      <inertia
        ixx="0.0046013275103996"
        ixy="-7.56314231045415E-39"
        ixz="-4.17161150360145E-36"
        iyy="0.0046013275103996"
        iyz="-8.30428564488929E-36"
        izz="0.00850174046700706" />
    </inertial>
    <visual>
      <origin
        xyz="0 0 0"
        rpy="0 0 0" />
      <geometry>
        <mesh
          filename="package://car_and_trailer/meshes/Rigth_Front_Wheel.STL" />
      </geometry>
      <material
        name="">
        <color
          rgba="0.792156862745098 0.819607843137255 0.933333333333333 1" />
      </material>
    </visual>
    <collision>
      <origin
        xyz="0 0 0"
        rpy="0 0 0" />
      <geometry>
        <mesh
          filename="package://car_and_trailer/meshes/Rigth_Front_Wheel.STL" />
      </geometry>
    </collision>
  </link>
  <joint
    name="Rigth_Front_Wheel_joint"
    type="continuous">
    <origin
      xyz="-0.4826 1.0033 0.1651"
      rpy="3.14159265358979 -1.5707963267949 0" />
    <parent
      link="Steer_Right" />
    <child
      link="Rigth_Front_Wheel" />
    <axis
      xyz="0 0 1" />
  </joint>
  <link
    name="Right_Back_Wheel">
    <inertial>
      <origin
        xyz="-6.93889390390723E-18 1.38777878078145E-16 0.0254"
        rpy="0 0 0" />
      <mass
        value="1.62962959682594" />
      <inertia
        ixx="0.0046013275103996"
        ixy="-7.56314231045415E-39"
        ixz="-4.17161150360144E-36"
        iyy="0.0046013275103996"
        iyz="-8.30428564488929E-36"
        izz="0.00850174046700706" />
    </inertial>
    <visual>
      <origin
        xyz="0 0 0"
        rpy="0 0 0" />
      <geometry>
        <mesh
          filename="package://car_and_trailer/meshes/Right_Back_Wheel.STL" />
      </geometry>
      <material
        name="">
        <color
          rgba="0.792156862745098 0.819607843137255 0.933333333333333 1" />
      </material>
    </visual>
    <collision>
      <origin
        xyz="0 0 0"
        rpy="0 0 0" />
      <geometry>
        <mesh
          filename="package://car_and_trailer/meshes/Right_Back_Wheel.STL" />
      </geometry>
    </collision>
  </link>
  <joint
    name="Right_Back_Wheel_joint"
    type="continuous">
    <origin
      xyz="0.4826 0.0381000000000003 -0.1651"
      rpy="1.5707963267949 0 1.5707963267949" />
    <parent
      link="base_link" />
    <child
      link="Right_Back_Wheel" />
    <axis
      xyz="0 0 1" />
  </joint>
  <link
    name="Left_Back_Wheel">
    <inertial>
      <origin
        xyz="0 1.38777878078145E-16 -6.93889390390723E-18"
        rpy="0 0 0" />
      <mass
        value="1.62962959682595" />
      <inertia
        ixx="0.00460132751039961"
        ixy="-7.56314231045466E-39"
        ixz="2.38823524459631E-19"
        iyy="0.00460132751039961"
        iyz="-8.3042856448893E-36"
        izz="0.00850174046700706" />
    </inertial>
    <visual>
      <origin
        xyz="0 0 0"
        rpy="0 0 0" />
      <geometry>
        <mesh
          filename="package://car_and_trailer/meshes/Left_Back_Wheel.STL" />
      </geometry>
      <material
        name="">
        <color
          rgba="0.792156862745098 0.819607843137255 0.933333333333333 1" />
      </material>
    </visual>
    <collision>
      <origin
        xyz="0 0 0"
        rpy="0 0 0" />
      <geometry>
        <mesh
          filename="package://car_and_trailer/meshes/Left_Back_Wheel.STL" />
      </geometry>
    </collision>
  </link>
  <joint
    name="Left_Back_Wheel_joint"
    type="continuous">
    <origin
      xyz="0 0.0381000000000003 -0.1651"
      rpy="1.5707963267949 0 1.5707963267949" />
    <parent
      link="base_link" />
    <child
      link="Left_Back_Wheel" />
    <axis
      xyz="0 0 1" />
  </joint>
  <link
    name="Lidar">
    <inertial>
      <origin
        xyz="0 0 0.0508"
        rpy="0 0 0" />
      <mass
        value="0.0514814798763057" />
      <inertia
        ixx="4.63609173816422E-05"
        ixy="1.91171029335894E-54"
        ixz="-4.83762878413658E-38"
        iyy="4.63609173816422E-05"
        iyz="-6.41845928115206E-38"
        izz="4.15172394462466E-06" />
    </inertial>
    <visual>
      <origin
        xyz="0 0 0"
        rpy="0 0 0" />
      <geometry>
        <mesh
          filename="package://car_and_trailer/meshes/Lidar.STL" />
      </geometry>
      <material
        name="">
        <color
          rgba="0.792156862745098 0.819607843137255 0.933333333333333 1" />
      </material>
    </visual>
    <collision>
      <origin
        xyz="0 0 0"
        rpy="0 0 0" />
      <geometry>
        <mesh
          filename="package://car_and_trailer/meshes/Lidar.STL" />
      </geometry>
    </collision>
  </link>
  <joint
    name="Lidar_joint"
    type="continuous">
    <origin
      xyz="0.254 0.508 0.1016"
      rpy="0 0 0" />
    <parent
      link="base_link" />
    <child
      link="Lidar" />
    <axis
      xyz="0 0 1" />
  </joint>
  <gazebo reference="Lidar">
  <sensor name="lidar" type="ray">
    <pose>0.0 0.0 0.0 0 0 0</pose>
    <always_on>true</always_on>
    <visualize>true</visualize>
    <update_rate>5</update_rate>
    <ray>
      <scan>
        <horizontal>
          <samples>360</samples>
          <resolution>1.00000</resolution>
          <min_angle>0.000000</min_angle>
          <max_angle>6.280000</max_angle>
        </horizontal>
      </scan>
      <range>
        <min>0.120000</min>
        <max>3.5</max>
        <resolution>0.015000</resolution>
      </range>
      <noise>
        <type>gaussian</type>
        <mean>0.0</mean>
        <stddev>0.01</stddev>
      </noise>
    </ray>
    <plugin name="scan" filename="libgazebo_ros_ray_sensor.so">
      <ros>
        <remapping>~/out:=scan</remapping>
      </ros>
      <output_type>sensor_msgs/LaserScan</output_type>
      <frame_name>Lidar</frame_name>
    </plugin>
  </sensor>
  </gazebo>
  <link
    name="Trailer">
    <inertial>
      <origin
        xyz="1.66533453693773E-16 -0.804111102029834 0.0275105834465963"
        rpy="0 0 0" />
      <mass
        value="27.2755326758408" />
      <inertia
        ixx="4.31133111414126"
        ixy="6.65415782568477E-16"
        ixz="-2.22750825253046E-16"
        iyy="0.66836978637258"
        iyz="-0.100077621756449"
        izz="4.58294264392293" />
    </inertial>
    <visual>
      <origin
        xyz="0 0 0"
        rpy="0 0 0" />
      <geometry>
        <mesh
          filename="package://car_and_trailer/meshes/Trailer.STL" />
      </geometry>
      <material
        name="">
        <color
          rgba="0.792156862745098 0.819607843137255 0.933333333333333 1" />
      </material>
    </visual>
    <collision>
      <origin
        xyz="0 0 0"
        rpy="0 0 0" />
      <geometry>
        <mesh
          filename="package://car_and_trailer/meshes/Trailer.STL" />
      </geometry>
    </collision>
  </link>
  <joint
    name="Trailer_joint"
    type="continuous">
    <origin
      xyz="0.254 0.0254 0"
      rpy="0 0 0" />
    <parent
      link="base_link" />
    <child
      link="Trailer" />
    <axis
      xyz="0 0 1" />
  </joint>
  <link
    name="Trailer_Left_Wheel">
    <inertial>
      <origin
        xyz="0 4.32667268468867E-17 -0.0254"
        rpy="0 0 0" />
      <mass
        value="1.62962959682595" />
      <inertia
        ixx="0.00460132751039961"
        ixy="-2.71050543121376E-20"
        ixz="4.27969795118175E-19"
        iyy="0.00460132751039961"
        iyz="1.30847375225861E-20"
        izz="0.00850174046700706" />
    </inertial>
    <visual>
      <origin
        xyz="0 0 0"
        rpy="0 0 0" />
      <geometry>
        <mesh
          filename="package://car_and_trailer/meshes/Trailer_Left_Wheel.STL" />
      </geometry>
      <material
        name="">
        <color
          rgba="0.792156862745098 0.819607843137255 0.933333333333333 1" />
      </material>
    </visual>
    <collision>
      <origin
        xyz="0 0 0"
        rpy="0 0 0" />
      <geometry>
        <mesh
          filename="package://car_and_trailer/meshes/Trailer_Left_Wheel.STL" />
      </geometry>
    </collision>
  </link>
  <joint
    name="Trailer_Left_Wheel_joint"
    type="continuous">
    <origin
      xyz="-0.2286 -0.44477638939552 -0.1651"
      rpy="1.5707963267949 0.0427063277818672 1.5707963267949" />
    <parent
      link="Trailer" />
    <child
      link="Trailer_Left_Wheel" />
    <axis
      xyz="0 0 1" />
  </joint>
  <link
    name="Trailer_Right_Wheel">
    <inertial>
      <origin
        xyz="0 4.32667268468867E-17 0.0253999999999999"
        rpy="0 0 0" />
      <mass
        value="1.62962959682594" />
      <inertia
        ixx="0.0046013275103996"
        ixy="-7.56314231044211E-39"
        ixz="3.36924666781802E-19"
        iyy="0.0046013275103996"
        iyz="-8.30428564488929E-36"
        izz="0.00850174046700706" />
    </inertial>
    <visual>
      <origin
        xyz="0 0 0"
        rpy="0 0 0" />
      <geometry>
        <mesh
          filename="package://car_and_trailer/meshes/Trailer_Right_Wheel.STL" />
      </geometry>
      <material
        name="">
        <color
          rgba="0.792156862745098 0.819607843137255 0.933333333333333 1" />
      </material>
    </visual>
    <collision>
      <origin
        xyz="0 0 0"
        rpy="0 0 0" />
      <geometry>
        <mesh
          filename="package://car_and_trailer/meshes/Trailer_Right_Wheel.STL" />
      </geometry>
    </collision>
  </link>
  <joint
    name="Trailer_Right_Wheel_joint"
    type="continuous">
    <origin
      xyz="0.2286 -0.4448 -0.1651"
      rpy="1.5708 0 1.5708" />
    <parent
      link="Trailer" />
    <child
      link="Trailer_Right_Wheel" />
    <axis
      xyz="0 0 1" />
  </joint>
  <link
    name="Trailer_Left_Back_Wheel">
    <inertial>
      <origin
        xyz="0 8.32667268468867E-17 -0.0254"
        rpy="0 0 0" />
      <mass
        value="1.62962959682595" />
      <inertia
        ixx="0.00460132751039961"
        ixy="-6.7762635780344E-20"
        ixz="4.27969795118175E-19"
        iyy="0.00460132751039961"
        iyz="1.30847375225861E-20"
        izz="0.00850174046700706" />
    </inertial>
    <visual>
      <origin
        xyz="0 0 0"
        rpy="0 0 0" />
      <geometry>
        <mesh
          filename="package://car_and_trailer/meshes/Trailer_Left_Back_Wheel.STL" />
      </geometry>
      <material
        name="">
        <color
          rgba="0.792156862745098 0.819607843137255 0.933333333333333 1" />
      </material>
    </visual>
    <collision>
      <origin
        xyz="0 0 0"
        rpy="0 0 0" />
      <geometry>
        <mesh
          filename="package://car_and_trailer/meshes/Trailer_Left_Back_Wheel.STL" />
      </geometry>
    </collision>
  </link>
  <joint
    name="Trailer_Left_Back_Wheel_joint"
    type="continuous">
    <origin
      xyz="-0.2286 -1.2448 -0.1651"
      rpy="1.5708 0.042706 1.5708" />
    <parent
      link="Trailer" />
    <child
      link="Trailer_Left_Back_Wheel" />
    <axis
      xyz="0 0 1" />
  </joint>
  <link
    name="Trailer_Right_Back_Wheel">
    <inertial>
      <origin
        xyz="-2.22044604925031E-16 5.55111512312578E-17 0.0254"
        rpy="0 0 0" />
      <mass
        value="1.62962959682594" />
      <inertia
        ixx="0.0046013275103996"
        ixy="-7.56314231044298E-39"
        ixz="3.36924666781802E-19"
        iyy="0.0046013275103996"
        iyz="-8.30428564488929E-36"
        izz="0.00850174046700706" />
    </inertial>
    <visual>
      <origin
        xyz="0 0 0"
        rpy="0 0 0" />
      <geometry>
        <mesh
          filename="package://car_and_trailer/meshes/Trailer_Right_Back_Wheel.STL" />
      </geometry>
      <material
        name="">
        <color
          rgba="0.792156862745098 0.819607843137255 0.933333333333333 1" />
      </material>
    </visual>
    <collision>
      <origin
        xyz="0 0 0"
        rpy="0 0 0" />
      <geometry>
        <mesh
          filename="package://car_and_trailer/meshes/Trailer_Right_Back_Wheel.STL" />
      </geometry>
    </collision>
  </link>
  <joint
    name="Trailer_Right_Back_Wheel_joint"
    type="continuous">
    <origin
      xyz="0.2286 -1.2448 -0.1651"
      rpy="1.5708 0 1.5708" />
    <parent
      link="Trailer" />
    <child
      link="Trailer_Right_Back_Wheel" />
    <axis
      xyz="0 0 1" />
  </joint>

  <ros2_control name="GazeboSystem" type="system">
    <hardware>
        <plugin>gazebo_ros2_control/GazeboSystem</plugin>
    </hardware>
 
    <!-- # Velocity Controllers -->
    <joint name="Right_Back_Wheel_joint">
        <command_interface name="velocity">
            <param name="min">-1000.0</param>
            <param name="max">1000.0</param>
        </command_interface>
        <state_interface name="velocity"/>
    </joint>

    <joint name="Left_Back_Wheel_joint">
        <command_interface name="velocity">
            <param name="min">-1000.0</param>
            <param name="max">1000.0</param>
        </command_interface>
        <state_interface name="velocity"/>
    </joint>

    <!-- # Position Controller -->
    <joint name="Left_Front_Wheel_joint">
        <command_interface name="position">
            <param name="min">-3.14</param>
            <param name="max">3.14</param>
        </command_interface>
        <state_interface name="position"/>
    </joint>
 
</ros2_control>

<gazebo>
    <plugin filename="libgazebo_ros2_control.so" name="gazebo_ros2_control">
        <parameters>$(find car_and_trailer)/config/control.yaml</parameters>
    </plugin>
</gazebo>

</robot>